В-в блоке try, если друг исключение не возникло,
вызывается метод fail(),
сигнализирующий о провале теста. В блоке catch,
если исключительная
ситуация произошла, проверяется на эквивалентность текстов
сообщения об ошибке.